Traceback (most recent call last):
  File "SpeedTester.py", line 64, in <module>
    main()
  File "SpeedTester.py", line 61, in main
    data = speedtester()
  File "SpeedTester.py", line 20, in speedtester
    st = Speedtest()
  File "/home/pi/.local/lib/python2.7/site-packages/speedtest.py", line 1091, in __init__
    self.get_config()
  File "/home/pi/.local/lib/python2.7/site-packages/speedtest.py", line 1123, in get_config
    raise ConfigRetrievalError(e)
speedtest.ConfigRetrievalError: <urlopen error [Errno -3] Temporary failure in name resolution>
Traceback (most recent call last):
  File "SpeedTester.py", line 65, in <module>
    main()
  File "SpeedTester.py", line 62, in main
    data = speedtester()
  File "SpeedTester.py", line 21, in speedtester
    st = Speedtest()
  File "/home/pi/.local/lib/python2.7/site-packages/speedtest.py", line 1091, in __init__
    self.get_config()
  File "/home/pi/.local/lib/python2.7/site-packages/speedtest.py", line 1123, in get_config
    raise ConfigRetrievalError(e)
speedtest.ConfigRetrievalError: <urlopen error [Errno -3] Temporary failure in name resolution>
Traceback (most recent call last):
  File "SpeedTester.py", line 65, in <module>
    main()
  File "SpeedTester.py", line 59, in main
    time.sleep(sec)
KeyboardInterrupt
Enter filename: Traceback (most recent call last):
  File "SpeedTester.py", line 25, in <module>
    FILENAME = input('Enter filename: ') + '.txt'
IOError: [Errno 9] Bad file descriptor
